* TOC
{:toc}

## 第七章：异常处理 

### 第一节：异常的概念以及异常处理机制和自定义异常 

在Python中，异常是一个事件，该事件在程序执行过程中发生，打断了代码的正常流程。Python使用异常对象来表示异常状态，并在遇到错误时引发异常。异常处理是一种构建健壮程序的关键机制，它可以捕获并响应运行时错误，防止程序意外终止。

#### 1.异常的概念 

异常是由于程序错误、用户输入错误、资源问题或其他不可预见的问题导致的一种运行时错误。在Python中，所有的异常都是从`BaseException`类派生的，而大多数应用级别的异常都是从`Exception`类派生的。

#### 2.异常处理机制 

Python使用`try`…`except`语句来处理异常。这允许程序捕获并响应特定类型的异常，执行一些清理工作或恢复操作。

 *  try块：尝试执行的代码块，可能会引发异常。
 *  except块：如果在try块中引发了异常，执行这个块中的代码。可以指定一个或多个异常类型来捕获特定的异常。
 *  else块（可选）：如果try块中没有异常发生，则执行这个块中的代码。
 *  finally块（可选）：无论是否发生异常，都会执行这个块中的代码。这通常用于执行一些清理工作，如关闭文件或释放资源。

#### 3.异常的引发 

使用`raise`语句可以引发一个指定的异常。可以提供一个异常实例或异常类（如果是异常类，将自动创建一个实例）。

#### 4.自定义异常 

通过继承`Exception`类或其子类来创建自定义异常。这允许你创建具有特定业务逻辑含义的异常。

示例

```python
try:
    x = int(input("请输入一个数字: "))
    y = 1 / x
except ValueError:
    print("您输入的不是有效的数字！")
except ZeroDivisionError:
    print("数字不能为0！")
else:
    print("一切正常！")
finally:
    print("执行清理工作。")
```

在这个示例中，如果用户输入的不是数字或输入了数字0，程序将分别捕获`ValueError`和`ZeroDivisionError`异常，并打印相应的错误消息。如果没有异常发生，将执行`else`块。无论是否发生异常，`finally`块都会执行。

总结

Python的异常处理机制提供了一种结构化和灵活的方式来处理运行时错误，使程序能够优雅地处理意外情况并保持稳定运行。通过合理使用异常处理，可以提高程序的健壮性和用户体验。

#### 5.python中关于异常的概念以及异常处理机制方向的面试题 

##### 面试题1 

面试题目：  
在Python中，如何使用`try`…`except`…`else`…`finally`语句来处理文件操作可能出现的异常？

面试考题知识点：

 *  Python的异常处理机制
 *  `try`…`except`…`else`…`finally`语句的用法
 *  文件操作可能出现的异常

考题知识点简要讲解：  
在Python中，可以使用`try`…`except`语句来捕获并处理可能出现的异常。在文件操作中，可能会出现如文件不存在、读写权限不足等异常，这些都可以通过`try`…`except`语句来捕获并处理。`else`语句块会在`try`块没有发生异常时执行，而`finally`语句块无论是否发生异常都会执行，通常用于进行清理工作，如关闭文件。

答案或代码：

```python
try:
    # 尝试打开文件
    with open('example.txt', 'r') as file:
        data = file.read()
except FileNotFoundError:
    # 文件不存在的异常
    print("文件未找到，请检查文件路径。")
except IOError:
    # 处理其他的IO错误
    print("读取文件时发生错误。")
else:
    # 如果没有异常发生
    print("文件读取成功！")
    print(data)
finally:
    # 无论是否发生异常都会执行的代码
    print("文件操作尝试完成。")
```

答案或代码解析：  
在这个代码示例中，我们使用`try`块尝试执行文件打开和读取操作。如果文件不存在，则会引发`FileNotFoundError`，并在`except`块中捕获并处理这个异常。如果发生了其他类型的IO错误，比如文件存在但用户没有读取权限，则会引发`IOError`，也在相应的`except`块中进行处理。如果文件成功打开并且没有引发任何异常，`else`块将执行，打印文件内容。最后，`finally`块无论是否发生异常都将执行，通常用于执行必要的清理工作，如在这个场景中，由于使用了`with`语句，文件将自动关闭，因此`finally`块可以用来打印一条结束消息。这个模式确保了程序在面对文件读取时的健壮性和错误处理能力。

##### 面试题2 

面试题目：  
在Python中，如何使用`try`…`except`语句捕获多种异常，并根据不同的异常类型执行不同的处理逻辑？

面试考题知识点：

 *  多异常处理
 *  `try`…`except`语句的高级用法
 *  异常的分支处理

考题知识点简要讲解：  
Python允许在一个`try`…`except`语句中捕获并处理多种类型的异常。这可以通过多个`except`块来实现，每个`except`块可以指定一个要捕获的异常类型。此外，还可以使用一个`except`块捕获多个异常类型，这些类型可以作为一个元组传递给`except`块。通过这种方式，程序可以根据不同的异常类型执行不同的错误处理逻辑，增强程序的健壮性和用户体验。

答案或代码：

```python
def divide(x, y):
    try:
        result = x / y
    except ZeroDivisionError:
        print("除数不能为零！")
    except TypeError:
        print("所有输入必须是数值类型！")
    except (ValueError, ArithmeticError) as e:
        print(f"发生了其他数学或值错误：{e}")
    else:
        print(f"结果是：{result}")
    finally:
        print("执行了除法运算")

# 正确的调用
divide(10, 2)
# 将引发ZeroDivisionError的调用
divide(10, 0)
# 将引发TypeError的调用
divide("10", "2")
```

答案或代码解析：  
在这个代码示例中，`divide`函数尝试执行除法运算，并通过`try`…`except`语句捕获并处理可能发生的几种异常。`ZeroDivisionError`和`TypeError`通过单独的`except`块捕获，以便针对这些特定错误类型提供定制化的错误消息。同时，`ValueError`和`ArithmeticError`通过一个共用的`except`块捕获，展示了如何同时处理多个异常类型。如果没有发生异常，`else`块将执行并打印运算结果。无论是否发生异常，`finally`块都会执行，这通常用于执行清理工作或结束消息的打印。这个例子展示了如何在Python中对多种异常进行细致和有组织的处理。

##### 面试题3 

面试题目：  
在Python中，如何自定义一个异常类，并在特定条件下引发该异常？

面试考题知识点：

 *  自定义异常类
 *  异常类的继承
 *  引发（raise）异常

考题知识点简要讲解：  
Python允许通过继承内置的`Exception`类来定义自定义异常。自定义异常类可以添加任何额外的属性和方法，这使得它们能够传递错误信息或执行相关的错误处理逻辑。引发自定义异常使用`raise`语句，可以在满足特定条件时触发这些异常，从而使错误处理更加灵活和具有表达力。

答案或代码：

```python
# 定义自定义异常类
class CustomError(Exception):
    def __init__(self, message="自定义错误"):
        self.message = message
        super().__init__(self.message)

# 函数中引发自定义异常
def check_value(x):
    if x < 0:
        raise CustomError("输入值不能为负")
    else:
        print(f"输入值为{x}")

try:
    check_value(-1)
except CustomError as e:
    print(e)

try:
    check_value(10)
except CustomError as e:
    print(e)
```

答案或代码解析：  
在这个示例中，我们首先定义了一个名为`CustomError`的自定义异常类，它继承自`Exception`类。通过重写`__init__`方法，`CustomError`可以接受一个自定义的错误消息，如果没有提供，则使用默认的错误消息。

在`check_value`函数中，使用`raise`语句引发`CustomError`异常，当输入的值小于0时触发。这个函数的调用被包裹在`try`…`except`块中，这样当`CustomError`被引发时，可以捕获它并打印出错误消息。

通过这个例子，我们展示了如何定义和使用自定义异常类来对特定的错误情况进行更细粒度的控制，这是提高Python程序健壮性和可维护性的有效方式。

##### 面试题4 

面试题目：  
在Python中，如何利用`try`…`except`语句实现异常链（Exception Chaining）？

面试考题知识点：

 *  异常链（Exception Chaining）
 *  `try`…`except`语句
 *  `raise ... from ...`语法

考题知识点简要讲解：  
异常链是Python 3中引入的一个特性，允许在处理一个异常时引发另一个异常，同时保留原始异常的信息。这通过使用`raise ... from ...`语法实现。这种机制有助于调试，因为它可以显示异常发生的完整路径，而不仅仅是最后引发的异常。在异常处理代码中使用`raise new_exception from original_exception`可以明确指出新的异常是在尝试处理原始异常时引发的。

答案或代码：

```python
def process_file(filename):
    try:
        open(filename, 'r')
    except FileNotFoundError as e:
        raise ValueError(f"文件 {filename} 未找到") from e

try:
    process_file("不存在的文件.txt")
except ValueError as e:
    print(f"处理文件时发生错误：{e}")
    print(f"原始异常：{e.__cause__}")
```

答案或代码解析：  
在这个示例中，`process_file`函数尝试打开一个文件。如果文件不存在，`FileNotFoundError`异常将被捕获。在`except`块中，我们使用`raise ... from ...`语法引发一个新的`ValueError`异常，并将原始的`FileNotFoundError`异常作为原因附加上去。这样，当处理`ValueError`异常时，我们可以访问到`__cause__`属性，了解到引发`ValueError`的原始异常是什么。

当尝试处理一个不存在的文件时，首先会捕获到`FileNotFoundError`异常，然后引发一个`ValueError`异常，并保留了原始异常的信息。通过打印出的错误信息和原始异常，我们可以清晰地看到异常链，这对于调试和解决问题非常有帮助。

这个面试题展示了如何在Python中使用异常链来提高错误处理的透明度和可追踪性，这是编写易于维护和调试的程序的一个重要技巧。

##### 面试题5 

面试题目：  
在Python中，如何使用`try`…`except`语句捕获特定异常并同时获取异常的错误信息？

面试考题知识点：

 *  捕获特定异常
 *  获取并使用异常的错误信息
 *  `try`…`except`语句的用法

考题知识点简要讲解：  
在Python中，`try`…`except`语句不仅可以用于捕获异常，还可以获取异常对象本身，从而访问到异常的详细信息。这是通过在`except`语句后跟异常类型和一个变量来实现的。这个变量绑定到了异常实例上，可以用来访问异常的属性，如错误消息等。这种方法对于记录错误详情、向用户提供更详细的反馈或根据错误信息做出不同的处理决策非常有用。

答案或代码：

```python
def divide(x, y):
    try:
        result = x / y
    except ZeroDivisionError as e:
        return f"除法失败：{e}"
    else:
        return f"结果是：{result}"

# 正确的调用
print(divide(10, 2))  # 输出: 结果是：5.0

# 将引发ZeroDivisionError的调用
print(divide(10, 0))  # 输出: 除法失败：division by zero
```

答案或代码解析：  
在这个示例中，`divide`函数尝试执行除法运算。如果除数为0，则会引发`ZeroDivisionError`异常。在`except`块中，我们捕获了这个异常并将其绑定到变量`e`上。这使我们能够使用`e`来访问异常的错误消息，并将其包含在返回的字符串中。如果没有发生异常，`else`块将执行，并返回运算结果。

通过捕获异常并使用异常的错误信息，我们能够提供更具体的错误反馈，这对于调试和向用户报告错误非常有帮助。这个面试题展示了如何在Python中有效地使用异常处理机制来增强程序的健壮性和用户体验。

##### 面试题6 

面试题目：  
在Python中，如何利用`try`…`except`语句实现对函数执行过程中可能发生的多种异常进行日志记录？

面试考题知识点：

 *  异常处理
 *  日志记录
 *  多异常捕获

考题知识点简要讲解：  
在Python中，`try`…`except`语句可以用来捕获并处理在执行特定代码块时可能发生的异常。通过在`except`块中添加日志记录逻辑，我们可以记录发生的异常信息，这对于程序的调试和运行时监控非常有用。当需要针对多种不同的异常执行相似的日志记录操作时，可以使用多个`except`块来分别捕获和记录这些异常，或者使用一个`except`块捕获所有异常并通过检查异常类型来进行差异化处理。

答案或代码：

```python
import logging

# 配置日志记录器
logging.basicConfig(level=logging.INFO, format='%(asctime)s - %(levelname)s - %(message)s')

def risky_operation():
    try:
        # 模拟可能引发不同异常的操作
        x = int("not a number")
    except ValueError as e:
        logging.error("ValueError occurred: %s", e)
        raise
    except ZeroDivisionError as e:
        logging.error("ZeroDivisionError occurred: %s", e)
        raise
    except Exception as e:
        logging.error("Unexpected error: %s", e)
        raise

try:
    risky_operation()
except Exception as e:
    print(f"An error occurred: {e}")
```

答案或代码解析：  
在这个示例中，`risky_operation`函数中的代码尝试执行一个可能引发多种异常的操作。我们使用了三个`except`块来分别捕获`ValueError`、`ZeroDivisionError`和其他未预期的异常。在每个`except`块中，我们使用`logging.error`函数记录了异常信息，包括异常类型和描述。通过`raise`语句，我们将异常重新抛出，允许它在函数外部被捕获。这样，我们即记录了异常信息，又没有阻止异常的进一步传播。

这个面试题展示了如何在Python中结合异常处理和日志记录来增强程序的健壮性和可维护性，特别是在处理可能引发多种异常的复杂操作时。通过适当的日志记录，我们可以获得程序运行时发生错误的详细信息，这对于问题的诊断和解决至关重要。

##### 面试题7 

面试题目：  
在Python中，如何使用`try`…`except`语句捕获异常，同时确保某些代码块无论是否发生异常都会执行？

面试考题知识点：

 *  异常处理
 *  `try`…`except`…`finally`语句
 *  确保代码执行

考题知识点简要讲解：  
Python的`try`…`except`语句用于捕获和处理异常。为了确保某些代码块无论是否发生异常都会执行，可以使用`finally`子句。`finally`子句中的代码在`try`块结束时总是执行，无论是否发生了异常。这对于资源管理非常重要，比如在处理文件、网络连接等资源时，确保这些资源在使用完毕后能够被正确关闭或释放。

答案或代码：

```python
def divide(x, y):
    try:
        result = x / y
    except ZeroDivisionError:
        print("除数不能为0.")
        return None
    else:
        print("结果是:", result)
    finally:
        print("执行除法运算的尝试结束.")

# 正确的调用
divide(10, 2)

# 将引发ZeroDivisionError的调用
divide(10, 0)
```

答案或代码解析：  
在这个示例中，`divide`函数尝试执行除法运算。`try`块中包含可能引发异常的代码。如果`y`为0，则会引发`ZeroDivisionError`，在`except`块中捕获此异常，并打印一条错误消息。如果没有发生异常，`else`块将执行，打印出除法的结果。无论是否发生异常，`finally`块中的代码都会执行，打印一条消息表明除法运算尝试已经结束。这确保了，无论操作的结果如何，都有机会执行一些清理工作或结束操作。

这个面试题展示了如何在Python中使用`try`…`except`…`finally`语句来处理异常，同时确保无论是否发生异常，都能执行特定的代码块。这种模式在需要管理资源或需要确保某些操作一定会执行的场景中特别有用。

##### 面试题8 

面试题目：  
在Python中，如何利用上下文管理器（context manager）和`with`语句来处理可能在文件操作中发生的异常？

面试考题知识点：

 *  上下文管理器和`with`语句
 *  文件操作中的异常处理
 *  自动资源管理

考题知识点简要讲解：  
上下文管理器是一个对象，定义了在执行代码块前后应该发生的操作。它通常与`with`语句一起使用，以确保无论是否发生异常，都可以执行一些"清理"工作，如关闭文件。这是通过上下文管理器的`__enter__`和`__exit__`魔术方法来实现的。`with`语句可以帮助简化异常处理，因为它可以自动处理资源的释放，即使在发生异常时也是如此。

答案或代码：

```python
def read_file(filename):
    try:
        with open(filename, 'r') as file:
            return file.read()
    except FileNotFoundError as e:
        print(f"文件未找到: {e}")
        return None
    except IOError as e:
        print(f"读取文件时发生错误: {e}")
        return None

# 尝试读取存在的文件
content = read_file('existing_file.txt')
print(content)

# 尝试读取不存在的文件
content = read_file('non_existing_file.txt')
print(content)
```

答案或代码解析：  
在这个示例中，`read_file`函数尝试打开并读取一个文件的内容。使用`with`语句和上下文管理器自动处理文件的打开和关闭。如果文件不存在，将引发`FileNotFoundError`，在`except`块中捕获并打印错误信息。如果发生其他类型的I/O错误，将引发`IOError`，同样在`except`块中处理。无论是否发生异常，`with`语句都会确保文件正确关闭。

这个面试题展示了如何利用上下文管理器和`with`语句来简化异常处理和资源管理。这种模式在处理文件或其他需要清理的资源时非常有用，可以防止资源泄漏，并使代码更加简洁和易于维护。

##### 面试题9 

面试题目：  
描述在Python中如何使用`try`…`except`语句来处理函数中的异常，并且重试失败的操作最多三次。

面试考题知识点：

 *  异常处理
 *  重试机制
 *  `try`…`except`语句

考题知识点简要讲解：  
在Python中，可以使用`try`…`except`语句来捕获异常，并在异常发生时执行一些特定的错误处理代码。有时，我们可能希望在失败时重试操作，特别是在面对偶发性错误时（如网络请求失败）。为此，我们可以在异常捕获后加入循环逻辑，以实现重试的效果。通常，我们会设置一个最大重试次数来避免无限循环。

答案或代码：

```python
import random

def perform_operation():
    if random.randint(0, 1) == 0:
        raise ValueError("模拟操作失败")

max_retries = 3
attempts = 0

while attempts < max_retries:
    try:
        perform_operation()
        print("操作成功")
        break
    except ValueError as e:
        attempts += 1
        print(f"发生异常：{e}。重试第 {attempts} 次")

if attempts == max_retries:
    print("操作重试失败")
```

答案或代码解析：  
在这个示例中，定义了一个`perform_operation`函数，该函数随机引发`ValueError`模拟操作失败。在主循环中，我们尝试执行`perform_operation`函数，并捕获可能出现的`ValueError`异常。如果操作成功，打印成功消息并退出循环。如果发生异常，增加尝试次数，并打印重试的次数。如果达到最大重试次数仍然失败，打印失败消息。

这个面试题展示了如何结合异常处理和重试逻辑来增强函数的健壮性，尤其适用于处理可能由于外部因素导致的偶发性错误。通过设置最大重试次数，我们可以防止无限重试，并在一定次数后放弃操作。

It seems there was a repetition in the request. However, I’ll provide a new example as requested.

##### 面试题10 

面试题目：  
编写一个Python函数`calculate_square_root`，该函数接受一个数字参数并返回其平方根。如果输入参数是负数，则函数应引发一个`ValueError`。展示如何调用这个函数并正确处理可能引发的异常。

面试考题知识点：

 *  自定义异常抛出
 *  异常处理
 *  函数定义

考题知识点简要讲解：  
在Python中，可以通过`raise`关键字引发异常。当函数接收到不符合要求的参数时，使用`raise`抛出异常是一种常见的做法。对于`calculate_square_root`函数，当输入参数为负数时，应引发`ValueError`。在调用该函数时，使用`try`…`except`语句来捕获并处理这个异常，可以提高程序的健壮性和用户友好性。

答案或代码：

```python
import math

def calculate_square_root(n):
    if n < 0:
        raise ValueError("不能为负数。")
    return math.sqrt(n)

try:
    result = calculate_square_root(-1)
    print(result)
except ValueError as e:
    print(f"错误：{e}")

try:
    result = calculate_square_root(9)
    print(f"9的平方根是：{result}")
except ValueError as e:
    print(f"错误：{e}")
```

答案或代码解析：  
在这个示例中，`calculate_square_root`函数首先检查输入参数`n`是否为负数。如果是，函数将引发一个`ValueError`，并传递一个描述性错误消息。当调用这个函数时，我们使用`try`…`except`语句来捕获可能发生的`ValueError`。如果捕获到这个异常，将打印出错误信息。如果没有异常发生（如当`n`为9时），函数将计算并返回平方根值。

这个面试题展示了如何在Python中自定义异常抛出，并通过异常处理机制确保程序在面对非预期输入时能够优雅地处理错误情况。这种方法对于构建健壮且用户友好的应用程序至关重要。